Workbook

Sheet Summary
A1: 普通级 Software Developer 简历初筛与20人多样化小样本
A4: 初筛池 | C4: 20人小样本 | E4: 强 / 中 / 弱 | G4: 岗位标签
A5: =COUNTA('Initial Pool'!$B$2:$B$397) | C5: =COUNTA('Sample 20'!$B$2:$B$21) | E5: =COUNTIF('Sample 20'!$D$2:$D$21,"强")&" / "&COUNTIF('Sample 20'!$D$2:$D$21,"中")&" / "&COUNTIF('Sample 20'!$D$2:$D$21,"弱") | G5: Software_Developer → 普通级 Software Developer
A8: 第一次筛选条件
A9: 1 | B9: 唯一标准标签严格等于 Software_Developer
A10: 2 | B10: 来源批次严格等于 soft_dav_part_1
A11: 3 | B11: 原始标题严格等于 Software Developer；排除Senior、Junior、Principal、Lead、Intern及Software Engineer、Web Developer等相邻岗位
A12: 4 | B12: 正文长度1,200–20,000字符，至少1段日期化工作经历和3类开发关键词
A13: 5 | B13: windows-1252解码为UTF-8；只整理可靠的标准章节标题，不补造内容
A15: 内容指标 | B15: 初筛池数量 | C15: 初筛池占比 | D15: 20人数量 | E15: 20人占比
A16: 有Skills段 | B16: =COUNTIF('Initial Pool'!$L$2:$L$397,"是") | C16: =B16/$A$5 | D16: =COUNTIF('Sample 20'!$L$2:$L$21,"是") | E16: =D16/$C$5
A17: 有证书/执照 | B17: =COUNTIF('Initial Pool'!$M$2:$M$397,"是") | C17: =B17/$A$5 | D17: =COUNTIF('Sample 20'!$M$2:$M$21,"是") | E17: =D17/$C$5
A18: 有Awards/Honors | B18: =COUNTIF('Initial Pool'!$N$2:$N$397,"是") | C18: =B18/$A$5 | D18: =COUNTIF('Sample 20'!$N$2:$N$21,"是") | E18: =D18/$C$5
A19: 有量化成果/成就 | B19: =COUNTIF('Initial Pool'!$O$2:$O$397,"是") | C19: =B19/$A$5 | D19: =COUNTIF('Sample 20'!$O$2:$O$21,"是") | E19: =D19/$C$5
A20: 有个人链接 | B20: =COUNTIF('Initial Pool'!$P$2:$P$397,"是") | C20: =B20/$A$5 | D20: =COUNTIF('Sample 20'!$P$2:$P$21,"是") | E20: =D20/$C$5
A21: 有项目/GitHub/Open Source | B21: =COUNTIF('Initial Pool'!$R$2:$R$397,"是") | C21: =B21/$A$5 | D21: =COUNTIF('Sample 20'!$R$2:$R$21,"是") | E21: =D21/$C$5
A22: 3段及以上工作经历 | B22: =COUNTIF('Initial Pool'!$I$2:$I$397,">=3") | C22: =B22/$A$5 | D22: =COUNTIF('Sample 20'!$I$2:$I$21,">=3") | E22: =D22/$C$5
A23: Bachelor及以上 | B23: =COUNTIF('Initial Pool'!$G$2:$G$397,"Bachelor")+COUNTIF('Initial Pool'!$G$2:$G$397,"Master")+COUNTIF('Initial Pool'!$G$2:$G$397,"Doctorate") | C23: =B23/$A$5 | D23: =COUNTIF('Sample 20'!$G$2:$G$21,"Bachelor")+COUNTIF('Sample 20'!$G$2:$G$21,"Master")+COUNTIF('Sample 20'!$G$2:$G$21,"Doctorate") | E23: =D23/$C$5
A25: 重要说明
A26: “强 / 中 / 弱”只描述简历中可见证据的完整度与丰富度，不代表候选人的真实能力、人格、录用结论或岗位适配度。所有样本的原始标题均严格等于Software Developer；20人小样本按7强、7中、6弱配置，并兼顾学历、工作经历、技术栈、行业、证书、奖项、成果、链接和项目经历的差异。最终20份均通过实际ReportLab PDF页数预检，成品不超过2页。

Sheet Initial Pool
A1: 入选20人 | B1: Candidate ID | C1: 原始标题 | D1: 分类 | E1: 内容证据分 | F1: 资历层级 | G1: 教育层次 | H1: 教育分 | I1: 工作经历数 | J1: 技术关键词数 | K1: 明确技术证书 | L1: 有Skills段 | M1: 有证书/执照 | N1: 有Awards/Honors | O1: 有量化成果/成就 | P1: 有个人链接 | Q1: 有补充信息 | R1: 有项目/GitHub/Open Source | S1: 正文字符数 | T1: 技术方向 | U1: 行业背景 | V1: 原始来源
A2: =IF(COUNTIF('Sample 20'!$B$2:$B$21,B2)>0,"是","") | B2: 20509 | C2: Software Developer | D2: =IF(E2>='Scoring Rules'!$B$3,"强",IF(E2>='Scoring Rules'!$B$4,"中","弱")) | E2: =MIN(100,H2+IF(I2>=5,'Scoring Rules'!$B$16,IF(I2>=3,'Scoring Rules'!$B$17,IF(I2>=1,'Scoring Rules'!$B$18,'Scoring Rules'!$B$19)))+IF(L2="是",'Scoring Rules'!$B$22,0)+MIN(J2*'Scoring Rules'!$B$23,'Scoring Rules'!$B$24)+IF(M2="是",'Scoring Rules'!$B$25,0)+MIN((IF(K2="",0,LEN(K2)-LEN(SUBSTITUTE(K2,";",""))+1))*'Scoring Rules'!$B$26,'Scoring Rules'!$B$27)+IF(N2="是",'Scoring Rules'!$B$28,0)+IF(O2="是",'Scoring Rules'!$B$29,0)+IF(P2="是",'Scoring Rules'!$B$30,0)+IF(Q2="是",'Scoring Rules'!$B$31,0)+IF(R2="是",'Scoring Rules'!$B$32,0)+IF(S2>=8000,'Scoring Rules'!$B$35,IF(S2>=4000,'Scoring Rules'!$B$36,IF(S2>=2000,'Scoring Rules'!$B$37,'Scoring Rules'!$B$38)))) | F2: Standard | G2: Master | H2: 16 | I2: 2 | J2: 8 | R2: 是 | S2: 2296 | T2: Frontend; Backend/API; Data/Database; Embedded/Systems | U2: Healthcare; Technology; Education/Research | V2: C:\Workspace\java\scrape_indeed\soft_dav_part_1\1.html#20783
A3: =IF(COUNTIF('Sample 20'!$B$2:$B$21,B3)>0,"是","") | B3: 20510 | C3: Software Developer | D3: =IF(E3>='Scoring Rules'!$B$3,"强",IF(E3>='Scoring Rules'!$B$4,"中","弱")) | E3: =MIN(100,H3+IF(I3>=5,'Scoring Rules'!$B$16,IF(I3>=3,'Scoring Rules'!$B$17,IF(I3>=1,'Scoring Rules'!$B$18,'Scoring Rules'!$B$19)))+IF(L3="是",'Scoring Rules'!$B$22,0)+MIN(J3*'Scoring Rules'!$B$23,'Scoring Rules'!$B$24)+IF(M3="是",'Scoring Rules'!$B$25,0)+MIN((IF(K3="",0,LEN(K3)-LEN(SUBSTITUTE(K3,";",""))+1))*'Scoring Rules'!$B$26,'Scoring Rules'!$B$27)+IF(N3="是",'Scoring Rules'!$B$28,0)+IF(O3="是",'Scoring Rules'!$B$29,0)+IF(P3="是",'Scoring Rules'!$B$30,0)+IF(Q3="是",'Scoring Rules'!$B$31,0)+IF(R3="是",'Scoring Rules'!$B$32,0)+IF(S3>=8000,'Scoring Rules'!$B$35,IF(S3>=4000,'Scoring Rules'!$B$36,IF(S3>=2000,'Scoring Rules'!$B$37,'Scoring Rules'!$B$38)))) | F3: Standard | G3: Unspecified | H3: 0 | I3: 1 | J3: 14 | R3: 是 | S3: 2301 | T3: Frontend; Backend/API; Mobile; Data/Database; Cloud/DevOps; Testing/Automation | U3: Technology; Education/Research | V3: C:\Workspace\java\scrape_indeed\soft_dav_part_1\10.html#20784
A4: =IF(COUNTIF('Sample 20'!$B$2:$B$21,B4)>0,"是","") | B4: 20516 | C4: Software Developer | D4: =IF(E4>='Scoring Rules'!$B$3,"强",IF(E4>='Scoring Rules'!$B$4,"中","弱")) | E4: =MIN(100,H4+IF(I4>=5,'Scoring Rules'!$B$16,IF(I4>=3,'Scoring Rules'!$B$17,IF(I4>=1,'Scoring Rules'!$B$18,'Scoring Rules'!$B$19)))+IF(L4="是",'Scoring Rules'!$B$22,0)+MIN(J4*'Scoring Rules'!$B$23,'Scoring Rules'!$B$24)+IF(M4="是",'Scoring Rules'!$B$25,0)+MIN((IF(K4="",0,LEN(K4)-LEN(SUBSTITUTE(K4,";",""))+1))*'Scoring Rules'!$B$26,'Scoring Rules'!$B$27)+IF(N4="是",'Scoring Rules'!$B$28,0)+IF(O4="是",'Scoring Rules'!$B$29,0)+IF(P4="是",'Scoring Rules'!$B$30,0)+IF(Q4="是",'Scoring Rules'!$B$31,0)+IF(R4="是",'Scoring Rules'!$B$32,0)+IF(S4>=8000,'Scoring Rules'!$B$35,IF(S4>=4000,'Scoring Rules'!$B$36,IF(S4>=2000,'Scoring Rules'!$B$37,'Scoring Rules'!$B$38)))) | F4: Standard | G4: Certificate | H4: 6 | I4: 5 | J4: 4 | S4: 1977 | T4: Data/Database | U4: Technology; Education/Research | V4: C:\Workspace\java\scrape_indeed\soft_dav_part_1\1004.html#20790
A5: =IF(COUNTIF('Sample 20'!$B$2:$B$21,B5)>0,"是","") | B5: 20522 | C5: Software Developer | D5: =IF(E5>='Scoring Rules'!$B$3,"强",IF(E5>='Scoring Rules'!$B$4,"中","弱")) | E5: =MIN(100,H5+IF(I5>=5,'Scoring Rules'!$B$16,IF(I5>=3,'Scoring Rules'!$B$17,IF(I5>=1,'Scoring Rules'!$B$18,'Scoring Rules'!$B$19)))+IF(L5="是",'Scoring Rules'!$B$22,0)+MIN(J5*'Scoring Rules'!$B$23,'Scoring Rules'!$B$24)+IF(M5="是",'Scoring Rules'!$B$25,0)+MIN((IF(K5="",0,LEN(K5)-LEN(SUBSTITUTE(K5,";",""))+1))*'Scoring Rules'!$B$26,'Scoring Rules'!$B$27)+IF(N5="是",'Scoring Rules'!$B$28,0)+IF(O5="是",'Scoring Rules'!$B$29,0)+IF(P5="是",'Scoring Rules'!$B$30,0)+IF(Q5="是",'Scoring Rules'!$B$31,0)+IF(R5="是",'Scoring Rules'!$B$32,0)+IF(S5>=8000,'Scoring Rules'!$B$35,IF(S5>=4000,'Scoring Rules'!$B$36,IF(S5>=2000,'Scoring Rules'!$B$37,'Scoring Rules'!$B$38)))) | F5: Standard | G5: Bachelor | H5: 12 | I5: 3 | J5: 18 | L5: 是 | O5: 是 | P5: 是 | Q5: 是 | R5: 是 | S5: 2330 | T5: Frontend; Backend/API; Data/Database; Cloud/DevOps; Embedded/Systems; Testing/Automation; Machine Learning | U5: Finance/Banking; Technology; Education/Research | V5: C:\Workspace\java\scrape_indeed\soft_dav_part_1\101.html#20796
A6: =IF(COUNTIF('Sample 20'!$B$2:$B$21,B6)>0,"是","") | B6: 20527 | C6: Software Developer | D6: =IF(E6>='Scoring Rules'!$B$3,"强",IF(E6>='Scoring Rules'!$B$4,"中","弱")) | E6: =MIN(100,H6+IF(I6>=5,'Scoring Rules'!$B$16,IF(I6>=3,'Scoring Rules'!$B$17,IF(I6>=1,'Scoring Rules'!$B$18,'Scoring Rules'!$B$19)))+IF(L6="是",'Scoring Rules'!$B$22,0)+MIN(J6*'Scoring Rules'!$B$23,'Scoring Rules'!$B$24)+IF(M6="是",'Scoring Rules'!$B$25,0)+MIN((IF(K6="",0,LEN(K6)-LEN(SUBSTITUTE(K6,";",""))+1))*'Scoring Rules'!$B$26,'Scoring Rules'!$B$27)+IF(N6="是",'Scoring Rules'!$B$28,0)+IF(O6="是",'Scoring Rules'!$B$29,0)+IF(P6="是",'Scoring Rules'!$B$30,0)+IF(Q6="是",'Scoring Rules'!$B$31,0)+IF(R6="是",'Scoring Rules'!$B$32,0)+IF(S6>=8000,'Scoring Rules'!$B$35,IF(S6>=4000,'Scoring Rules'!$B$36,IF(S6>=2000,'Scoring Rules'!$B$37,'Scoring Rules'!$B$38)))) | F6: Standard | G6: Unspecified | H6: 0 | I6: 4 | J6: 11 | R6: 是 | S6: 3681 | T6: Frontend; Backend/API | U6: Technology; Education/Research | V6: C:\Workspace\java\scrape_indeed\soft_dav_part_1\1014.html#20801
A7: =IF(COUNTIF('Sample 20'!$B$2:$B$21,B7)>0,"是","") | B7: 20540 | C7: Software Developer | D7: =IF(E7>='Scoring Rules'!$B$3,"强",IF(E7>='Scoring Rules'!$B$4,"中","弱")) | E7: =MIN(100,H7+IF(I7>=5,'Scoring Rules'!$B$16,IF(I7>=3,'Scoring Rules'!$B$17,IF(I7>=1,'Scoring Rules'!$B$18,'Scoring Rules'!$B$19)))+IF(L7="是",'Scoring Rules'!$B$22,0)+MIN(J7*'Scoring Rules'!$B$23,'Scoring Rules'!$B$24)+IF(M7="是",'Scoring Rules'!$B$25,0)+MIN((IF(K7="",0,LEN(K7)-LEN(SUBSTITUTE(K7,";",""))+1))*'Scoring Rules'!$B$26,'Scoring Rules'!$B$27)+IF(N7="是",'Scoring Rules'!$B$28,0)+IF(O7="是",'Scoring Rules'!$B$29,0)+IF(P7="是",'Scoring Rules'!$B$30,0)+IF(Q7="是",'Scoring Rules'!$B$31,0)+IF(R7="是",'Scoring Rules'!$B$32,0)+IF(S7>=8000,'Scoring Rules'!$B$35,IF(S7>=4000,'Scoring Rules'!$B$36,IF(S7>=2000,'Scoring Rules'!$B$37,'Scoring Rules'!$B$38)))) | F7: Standard | G7: Bachelor | H7: 12 | I7: 5 | J7: 19 | L7: 是 | P7: 是 | Q7: 是 | R7: 是 | S7: 4108 | T7: Frontend; Backend/API; Data/Database | U7: Finance/Banking; Healthcare; Technology; Education/Research | V7: C:\Workspace\java\scrape_indeed\soft_dav_part_1\1026.html#20814
A8: =IF(COUNTIF('Sample 20'!$B$2:$B$21,B8)>0,"是","") | B8: 20545 | C8: Software Developer | D8: =IF(E8>='Scoring Rules'!$B$3,"强",IF(E8>='Scoring Rules'!$B$4,"中","弱")) | E8: =MIN(100,H8+IF(I8>=5,'Scoring Rules'!$B$16,IF(I8>=3,'Scoring Rules'!$B$17,IF(I8>=1,'Scoring Rules'!$B$18,'Scoring Rules'!$B$19)))+IF(L8="是",'Scoring Rules'!$B$22,0)+MIN(J8*'Scoring Rules'!$B$23,'Scoring Rules'!$B$24)+IF(M8="是",'Scoring Rules'!$B$25,0)+MIN((IF(K8="",0,LEN(K8)-LEN(SUBSTITUTE(K8,";",""))+1))*'Scoring Rules'!$B$26,'Scoring Rules'!$B$27)+IF(N8="是",'Scoring Rules'!$B$28,0)+IF(O8="是",'Scoring Rules'!$B$29,0)+IF(P8="是",'Scoring Rules'!$B$30,0)+IF(Q8="是",'Scoring Rules'!$B$31,0)+IF(R8="是",'Scoring Rules'!$B$32,0)+IF(S8>=8000,'Scoring Rules'!$B$35,IF(S8>=4000,'Scoring Rules'!$B$36,IF(S8>=2000,'Scoring Rules'!$B$37,'Scoring Rules'!$B$38)))) | F8: Standard | G8: Master | H8: 16 | I8: 2 | J8: 15 | K8: PMP | L8: 是 | M8: 是 | O8: 是 | R8: 是 | S8: 3360 | T8: Frontend; Backend/API; Data/Database; Cloud/DevOps; Embedded/Systems; Testing/Automation | U8: Technology; Telecom; Education/Research | V8: C:\Workspace\java\scrape_indeed\soft_dav_part_1\1030.html#20819
A9: =IF(COUNTIF('Sample 20'!$B$2:$B$21,B9)>0,"是","") | B9: 20553 | C9: Software Developer | D9: =IF(E9>='Scoring Rules'!$B$3,"强",IF(E9>='Scoring Rules'!$B$4,"中","弱")) | E9: =MIN(100,H9+IF(I9>=5,'Scoring Rules'!$B$16,IF(I9>=3,'Scoring Rules'!$B$17,IF(I9>=1,'Scoring Rules'!$B$18,'Scoring Rules'!$B$19)))+IF(L9="是",'Scoring Rules'!$B$22,0)+MIN(J9*'Scoring Rules'!$B$23,'Scoring Rules'!$B$24)+IF(M9="是",'Scoring Rules'!$B$25,0)+MIN((IF(K9="",0,LEN(K9)-LEN(SUBSTITUTE(K9,";",""))+1))*'Scoring Rules'!$B$26,'Scoring Rules'!$B$27)+IF(N9="是",'Scoring Rules'!$B$28,0)+IF(O9="是",'Scoring Rules'!$B$29,0)+IF(P9="是",'Scoring Rules'!$B$30,0)+IF(Q9="是",'Scoring Rules'!$B$31,0)+IF(R9="是",'Scoring Rules'!$B$32,0)+IF(S9>=8000,'Scoring Rules'!$B$35,IF(S9>=4000,'Scoring Rules'!$B$36,IF(S9>=2000,'Scoring Rules'!$B$37,'Scoring Rules'!$B$38)))) | F9: Standard | G9: Bachelor | H9: 12 | I9: 4 | J9: 21 | L9: 是 | P9: 是 | Q9: 是 | R9: 是 | S9: 3779 | T9: Frontend; Backend/API; Mobile; Data/Database; Cloud/DevOps | U9: Technology; Education/Research | V9: C:\Workspace\java\scrape_indeed\soft_dav_part_1\1038.html#20827
A10: =IF(COUNTIF('Sample 20'!$B$2:$B$21,B10)>0,"是","") | B10: 20557 | C10: Software Developer | D10: =IF(E10>='Scoring Rules'!$B$3,"强",IF(E10>='Scoring Rules'!$B$4,"中","弱")) | E10: =MIN(100,H10+IF(I10>=5,'Scoring Rules'!$B$16,IF(I10>=3,'Scoring Rules'!$B$17,IF(I10>=1,'Scoring Rules'!$B$18,'Scoring Rules'!$B$19)))+IF(L10="是",'Scoring Rules'!$B$22,0)+MIN(J10*'Scoring Rules'!$B$23,'Scoring Rules'!$B$24)+IF(M10="是",'Scoring Rules'!$B$25,0)+MIN((IF(K10="",0,LEN(K10)-LEN(SUBSTITUTE(K10,";",""))+1))*'Scoring Rules'!$B$26,'Scoring Rules'!$B$27)+IF(N10="是",'Scoring Rules'!$B$28,0)+IF(O10="是",'Scoring Rules'!$B$29,0)+IF(P10="是",'Scoring Rules'!$B$30,0)+IF(Q10="是",'Scoring Rules'!$B$31,0)+IF(R10="是",'Scoring Rules'!$B$32,0)+IF(S10>=8000,'Scoring Rules'!$B$35,IF(S10>=4000,'Scoring Rules'!$B$36,IF(S10>=2000,'Scoring Rules'!$B$37,'Scoring Rules'!$B$38)))) | F10: Standard | G10: Bachelor | H10: 12 | I10: 3 | J10: 4 | L10: 是 | R10: 是 | S10: 2926 | T10: Data/Database; Testing/Automation | U10: Technology; Education/Research | V10: C:\Workspace\java\scrape_indeed\soft_dav_part_1\1041.html#20831
A11: =IF(COUNTIF('Sample 20'!$B$2:$B$21,B11)>0,"是","") | B11: 20589 | C11: Software Developer | D11: =IF(E11>='Scoring Rules'!$B$3,"强",IF(E11>='Scoring Rules'!$B$4,"中","弱")) | E11: =MIN(100,H11+IF(I11>=5,'Scoring Rules'!$B$16,IF(I11>=3,'Scoring Rules'!$B$17,IF(I11>=1,'Scoring Rules'!$B$18,'Scoring Rules'!$B$19)))+IF(L11="是",'Scoring Rules'!$B$22,0)+MIN(J11*'Scoring Rules'!$B$23,'Scoring Rules'!$B$24)+IF(M11="是",'Scoring Rules'!$B$25,0)+MIN((IF(K11="",0,LEN(K11)-LEN(SUBSTITUTE(K11,";",""))+1))*'Scoring Rules'!$B$26,'Scoring Rules'!$B$27)+IF(N11="是",'Scoring Rules'!$B$28,0)+IF(O11="是",'Scoring Rules'!$B$29,0)+IF(P11="是",'Scoring Rules'!$B$30,0)+IF(Q11="是",'Scoring Rules'!$B$31,0)+IF(R11="是",'Scoring Rules'!$B$32,0)+IF(S11>=8000,'Scoring Rules'!$B$35,IF(S11>=4000,'Scoring Rules'!$B$36,IF(S11>=2000,'Scoring Rules'!$B$37,'Scoring Rules'!$B$38)))) | F11: Standard | G11: Bachelor | H11: 12 | I11: 2 | J11: 12 | L11: 是 | S11: 1789 | T11: Frontend; Backend/API; Data/Database | U11: Technology; Education/Research | V11: C:\Workspace\java\scrape_indeed\soft_dav_part_1\1072.html#20865
A12: =IF(COUNTIF('Sample 20'!$B$2:$B$21,B12)>0,"是","") | B12: 20595 | C12: Software Developer | D12: =IF(E12>='Scoring Rules'!$B$3,"强",IF(E12>='Scoring Rules'!$B$4,"中","弱")) | E12: =MIN(100,H12+IF(I12>=5,'Scoring Rules'!$B$16,IF(I12>=3,'Scoring Rules'!$B$17,IF(I12>=1,'Scoring Rules'!$B$18,'Scoring Rules'!$B$19)))+IF(L12="是",'Scoring Rules'!$B$22,0)+MIN(J12*'Scoring Rules'!$B$23,'Scoring Rules'!$B$24)+IF(M12="是",'Scoring Rules'!$B$25,0)+MIN((IF(K12="",0,LEN(K12)-LEN(SUBSTITUTE(K12,";",""))+1))*'Scoring Rules'!$B$26,'Scoring Rules'!$B$27)+IF(N12="是",'Scoring Rules'!$B$28,0)+IF(O12="是",'Scoring Rules'!$B$29,0)+IF(P12="是",'Scoring Rules'!$B$30,0)+IF(Q12="是",'Scoring Rules'!$B$31,0)+IF(R12="是",'Scoring Rules'!$B$32,0)+IF(S12>=8000,'Scoring Rules'!$B$35,IF(S12>=4000,'Scoring Rules'!$B$36,IF(S12>=2000,'Scoring Rules'!$B$37,'Scoring Rules'!$B$38)))) | F12: Standard | G12: Bachelor | H12: 12 | I12: 2 | J12: 11 | L12: 是 | S12: 1643 | T12: Frontend; Backend/API; Mobile; Data/Database | U12: Healthcare; Technology; Consulting | V12: C:\Workspace\java\scrape_indeed\soft_dav_part_1\108.html#20873
A13: =IF(COUNTIF('Sample 20'!$B$2:$B$21,B13)>0,"是","") | B13: 20600 | C13: Software Developer | D13: =IF(E13>='Scoring Rules'!$B$3,"强",IF(E13>='Scoring Rules'!$B$4,"中","弱")) | E13: =MIN(100,H13+IF(I13>=5,'Scoring Rules'!$B$16,IF(I13>=3,'Scoring Rules'!$B$17,IF(I13>=1,'Scoring Rules'!$B$18,'Scoring Rules'!$B$19)))+IF(L13="是",'Scoring Rules'!$B$22,0)+MIN(J13*'Scoring Rules'!$B$23,'Scoring Rules'!$B$24)+IF(M13="是",'Scoring Rules'!$B$25,0)+MIN((IF(K13="",0,LEN(K13)-LEN(SUBSTITUTE(K13,";",""))+1))*'Scoring Rules'!$B$26,'Scoring Rules'!$B$27)+IF(N13="是",'Scoring Rules'!$B$28,0)+IF(O13="是",'Scoring Rules'!$B$29,0)+IF(P13="是",'Scoring Rules'!$B$30,0)+IF(Q13="是",'Scoring Rules'!$B$31,0)+IF(R13="是",'Scoring Rules'!$B$32,0)+IF(S13>=8000,'Scoring Rules'!$B$35,IF(S13>=4000,'Scoring Rules'!$B$36,IF(S13>=2000,'Scoring Rules'!$B$37,'Scoring Rules'!$B$38)))) | F13: Standard | G13: Master | H13: 16 | I13: 3 | J13: 20 | L13: 是 | R13: 是 | S13: 3003 | T13: Frontend; Backend/API; Data/Database; Cloud/DevOps; Machine Learning | U13: Government/Defense; Technology; Education/Research | V13: C:\Workspace\java\scrape_indeed\soft_dav_part_1\1084.html#20878
A14: =IF(COUNTIF('Sample 20'!$B$2:$B$21,B14)>0,"是","") | B14: 20605 | C14: SOFTWARE DEVELOPER | D14: =IF(E14>='Scoring Rules'!$B$3,"强",IF(E14>='Scoring Rules'!$B$4,"中","弱")) | E14: =MIN(100,H14+IF(I14>=5,'Scoring Rules'!$B$16,IF(I14>=3,'Scoring Rules'!$B$17,IF(I14>=1,'Scoring Rules'!$B$18,'Scoring Rules'!$B$19)))+IF(L14="是",'Scoring Rules'!$B$22,0)+MIN(J14*'Scoring Rules'!$B$23,'Scoring Rules'!$B$24)+IF(M14="是",'Scoring Rules'!$B$25,0)+MIN((IF(K14="",0,LEN(K14)-LEN(SUBSTITUTE(K14,";",""))+1))*'Scoring Rules'!$B$26,'Scoring Rules'!$B$27)+IF(N14="是",'Scoring Rules'!$B$28,0)+IF(O14="是",'Scoring Rules'!$B$29,0)+IF(P14="是",'Scoring Rules'!$B$30,0)+IF(Q14="是",'Scoring Rules'!$B$31,0)+IF(R14="是",'Scoring Rules'!$B$32,0)+IF(S14>=8000,'Scoring Rules'!$B$35,IF(S14>=4000,'Scoring Rules'!$B$36,IF(S14>=2000,'Scoring Rules'!$B$37,'Scoring Rules'!$B$38)))) | F14: Standard | G14: Master | H14: 16 | I14: 5 | J14: 20 | L14: 是 | Q14: 是 | R14: 是 | S14: 4912 | T14: Frontend; Backend/API; Data/Database; Testing/Automation | U14: Finance/Banking; Technology; Education/Research | V14: C:\Workspace\java\scrape_indeed\soft_dav_part_1\1089.html#20883
A15: =IF(COUNTIF('Sample 20'!$B$2:$B$21,B15)>0,"是","") | B15: 20611 | C15: Software Developer | D15: =IF(E15>='Scoring Rules'!$B$3,"强",IF(E15>='Scoring Rules'!$B$4,"中","弱")) | E15: =MIN(100,H15+IF(I15>=5,'Scoring Rules'!$B$16,IF(I15>=3,'Scoring Rules'!$B$17,IF(I15>=1,'Scoring Rules'!$B$18,'Scoring Rules'!$B$19)))+IF(L15="是",'Scoring Rules'!$B$22,0)+MIN(J15*'Scoring Rules'!$B$23,'Scoring Rules'!$B$24)+IF(M15="是",'Scoring Rules'!$B$25,0)+MIN((IF(K15="",0,LEN(K15)-LEN(SUBSTITUTE(K15,";",""))+1))*'Scoring Rules'!$B$26,'Scoring Rules'!$B$27)+IF(N15="是",'Scoring Rules'!$B$28,0)+IF(O15="是",'Scoring Rules'!$B$29,0)+IF(P15="是",'Scoring Rules'!$B$30,0)+IF(Q15="是",'Scoring Rules'!$B$31,0)+IF(R15="是",'Scoring Rules'!$B$32,0)+IF(S15>=8000,'Scoring Rules'!$B$35,IF(S15>=4000,'Scoring Rules'!$B$36,IF(S15>=2000,'Scoring Rules'!$B$37,'Scoring Rules'!$B$38)))) | F15: Standard | G15: Associate | H15: 8 | I15: 9 | J15: 19 | L15: 是 | P15: 是 | Q15: 是 | R15: 是 | S15: 3951 | T15: Frontend; Backend/API; Data/Database; Testing/Automation | U15: Technology; Education/Research | V15: C:\Workspace\java\scrape_indeed\soft_dav_part_1\1095.html#20890
A16: =IF(COUNTIF('Sample 20'!$B$2:$B$21,B16)>0,"是","") | B16: 20612 | C16: Software Developer | D16: =IF(E16>='Scoring Rules'!$B$3,"强",IF(E16>='Scoring Rules'!$B$4,"中","弱")) | E16: =MIN(100,H16+IF(I16>=5,'Scoring Rules'!$B$16,IF(I16>=3,'Scoring Rules'!$B$17,IF(I16>=1,'Scoring Rules'!$B$18,'Scoring Rules'!$B$19)))+IF(L16="是",'Scoring Rules'!$B$22,0)+MIN(J16*'Scoring Rules'!$B$23,'Scoring Rules'!$B$24)+IF(M16="是",'Scoring Rules'!$B$25,0)+MIN((IF(K16="",0,LEN(K16)-LEN(SUBSTITUTE(K16,";",""))+1))*'Scoring Rules'!$B$26,'Scoring Rules'!$B$27)+IF(N16="是",'Scoring Rules'!$B$28,0)+IF(O16="是",'Scoring Rules'!$B$29,0)+IF(P16="是",'Scoring Rules'!$B$30,0)+IF(Q16="是",'Scoring Rules'!$B$31,0)+IF(R16="是",'Scoring Rules'!$B$32,0)+IF(S16>=8000,'Scoring Rules'!$B$35,IF(S16>=4000,'Scoring Rules'!$B$36,IF(S16>=2000,'Scoring Rules'!$B$37,'Scoring Rules'!$B$38)))) | F16: Standard | G16: Master | H16: 16 | I16: 1 | J16: 16 | L16: 是 | Q16: 是 | R16: 是 | S16: 3240 | T16: Frontend; Backend/API; Data/Database; Cloud/DevOps; Testing/Automation | U16: Technology; Education/Research | V16: C:\Workspace\java\scrape_indeed\soft_dav_part_1\1096.html#20891
A17: =IF(COUNTIF('Sample 20'!$B$2:$B$21,B17)>0,"是","") | B17: 20613 | C17: Software Developer | D17: =IF(E17>='Scoring Rules'!$B$3,"强",IF(E17>='Scoring Rules'!$B$4,"中","弱")) | E17: =MIN(100,H17+IF(I17>=5,'Scoring Rules'!$B$16,IF(I17>=3,'Scoring Rules'!$B$17,IF(I17>=1,'Scoring Rules'!$B$18,'Scoring Rules'!$B$19)))+IF(L17="是",'Scoring Rules'!$B$22,0)+MIN(J17*'Scoring Rules'!$B$23,'Scoring Rules'!$B$24)+IF(M17="是",'Scoring Rules'!$B$25,0)+MIN((IF(K17="",0,LEN(K17)-LEN(SUBSTITUTE(K17,";",""))+1))*'Scoring Rules'!$B$26,'Scoring Rules'!$B$27)+IF(N17="是",'Scoring Rules'!$B$28,0)+IF(O17="是",'Scoring Rules'!$B$29,0)+IF(P17="是",'Scoring Rules'!$B$30,0)+IF(Q17="是",'Scoring Rules'!$B$31,0)+IF(R17="是",'Scoring Rules'!$B$32,0)+IF(S17>=8000,'Scoring Rules'!$B$35,IF(S17>=4000,'Scoring Rules'!$B$36,IF(S17>=2000,'Scoring Rules'!$B$37,'Scoring Rules'!$B$38)))) | F17: Standard | G17: Unspecified | H17: 0 | I17: 3 | J17: 16 | R17: 是 | S17: 3794 | T17: Frontend; Backend/API; Data/Database; Embedded/Systems; Testing/Automation | U17: Finance/Banking; Technology | V17: C:\Workspace\java\scrape_indeed\soft_dav_part_1\1097.html#20892
A18: =IF(COUNTIF('Sample 20'!$B$2:$B$21,B18)>0,"是","") | B18: 20616 | C18: Software developer | D18: =IF(E18>='Scoring Rules'!$B$3,"强",IF(E18>='Scoring Rules'!$B$4,"中","弱")) | E18: =MIN(100,H18+IF(I18>=5,'Scoring Rules'!$B$16,IF(I18>=3,'Scoring Rules'!$B$17,IF(I18>=1,'Scoring Rules'!$B$18,'Scoring Rules'!$B$19)))+IF(L18="是",'Scoring Rules'!$B$22,0)+MIN(J18*'Scoring Rules'!$B$23,'Scoring Rules'!$B$24)+IF(M18="是",'Scoring Rules'!$B$25,0)+MIN((IF(K18="",0,LEN(K18)-LEN(SUBSTITUTE(K18,";",""))+1))*'Scoring Rules'!$B$26,'Scoring Rules'!$B$27)+IF(N18="是",'Scoring Rules'!$B$28,0)+IF(O18="是",'Scoring Rules'!$B$29,0)+IF(P18="是",'Scoring Rules'!$B$30,0)+IF(Q18="是",'Scoring Rules'!$B$31,0)+IF(R18="是",'Scoring Rules'!$B$32,0)+IF(S18>=8000,'Scoring Rules'!$B$35,IF(S18>=4000,'Scoring Rules'!$B$36,IF(S18>=2000,'Scoring Rules'!$B$37,'Scoring Rules'!$B$38)))) | F18: Standard | G18: Unspecified | H18: 0 | I18: 1 | J18: 19 | R18: 是 | S18: 4663 | T18: Frontend; Backend/API; Mobile; Data/Database; Embedded/Systems | U18: Finance/Banking; Technology; Education/Research | V18: C:\Workspace\java\scrape_indeed\soft_dav_part_1\11.html#20895
A19: =IF(COUNTIF('Sample 20'!$B$2:$B$21,B19)>0,"是","") | B19: 20619 | C19: Software Developer | D19: =IF(E19>='Scoring Rules'!$B$3,"强",IF(E19>='Scoring Rules'!$B$4,"中","弱")) | E19: =MIN(100,H19+IF(I19>=5,'Scoring Rules'!$B$16,IF(I19>=3,'Scoring Rules'!$B$17,IF(I19>=1,'Scoring Rules'!$B$18,'Scoring Rules'!$B$19)))+IF(L19="是",'Scoring Rules'!$B$22,0)+MIN(J19*'Scoring Rules'!$B$23,'Scoring Rules'!$B$24)+IF(M19="是",'Scoring Rules'!$B$25,0)+MIN((IF(K19="",0,LEN(K19)-LEN(SUBSTITUTE(K19,";",""))+1))*'Scoring Rules'!$B$26,'Scoring Rules'!$B$27)+IF(N19="是",'Scoring Rules'!$B$28,0)+IF(O19="是",'Scoring Rules'!$B$29,0)+IF(P19="是",'Scoring Rules'!$B$30,0)+IF(Q19="是",'Scoring Rules'!$B$31,0)+IF(R19="是",'Scoring Rules'!$B$32,0)+IF(S19>=8000,'Scoring Rules'!$B$35,IF(S19>=4000,'Scoring Rules'!$B$36,IF(S19>=2000,'Scoring Rules'!$B$37,'Scoring Rules'!$B$38)))) | F19: Standard | G19: Bachelor | H19: 12 | I19: 4 | J19: 12 | L19: 是 | O19: 是 | P19: 是 | Q19: 是 | R19: 是 | S19: 2031 | T19: Frontend; Backend/API; Cloud/DevOps | U19: Technology; Education/Research | V19: C:\Workspace\java\scrape_indeed\soft_dav_part_1\1101.html#20898
A20: =IF(COUNTIF('Sample 20'!$B$2:$B$21,B20)>0,"是","") | B20: 20625 | C20: Software Developer | D20: =IF(E20>='Scoring Rules'!$B$3,"强",IF(E20>='Scoring Rules'!$B$4,"中","弱")) | E20: =MIN(100,H20+IF(I20>=5,'Scoring Rules'!$B$16,IF(I20>=3,'Scoring Rules'!$B$17,IF(I20>=1,'Scoring Rules'!$B$18,'Scoring Rules'!$B$19)))+IF(L20="是",'Scoring Rules'!$B$22,0)+MIN(J20*'Scoring Rules'!$B$23,'Scoring Rules'!$B$24)+IF(M20="是",'Scoring Rules'!$B$25,0)+MIN((IF(K20="",0,LEN(K20)-LEN(SUBSTITUTE(K20,";",""))+1))*'Scoring Rules'!$B$26,'Scoring Rules'!$B$27)+IF(N20="是",'Scoring Rules'!$B$28,0)+IF(O20="是",'Scoring Rules'!$B$29,0)+IF(P20="是",'Scoring Rules'!$B$30,0)+IF(Q20="是",'Scoring Rules'!$B$31,0)+IF(R20="是",'Scoring Rules'!$B$32,0)+IF(S20>=8000,'Scoring Rules'!$B$35,IF(S20>=4000,'Scoring Rules'!$B$36,IF(S20>=2000,'Scoring Rules'!$B$37,'Scoring Rules'!$B$38)))) | F20: Standard | G20: Master | H20: 16 | I20: 2 | J20: 10 | P20: 是 | R20: 是 | S20: 1503 | T20: Backend/API; Data/Database; Cloud/DevOps; Machine Learning | U20: Technology; Education/Research | V20: C:\Workspace\java\scrape_indeed\soft_dav_part_1\1107.html#20904
A21: =IF(COUNTIF('Sample 20'!$B$2:$B$21,B21)>0,"是","") | B21: 20629 | C21: Software Developer | D21: =IF(E21>='Scoring Rules'!$B$3,"强",IF(E21>='Scoring Rules'!$B$4,"中","弱")) | E21: =MIN(100,H21+IF(I21>=5,'Scoring Rules'!$B$16,IF(I21>=3,'Scoring Rules'!$B$17,IF(I21>=1,'Scoring Rules'!$B$18,'Scoring Rules'!$B$19)))+IF(L21="是",'Scoring Rules'!$B$22,0)+MIN(J21*'Scoring Rules'!$B$23,'Scoring Rules'!$B$24)+IF(M21="是",'Scoring Rules'!$B$25,0)+MIN((IF(K21="",0,LEN(K21)-LEN(SUBSTITUTE(K21,";",""))+1))*'Scoring Rules'!$B$26,'Scoring Rules'!$B$27)+IF(N21="是",'Scoring Rules'!$B$28,0)+IF(O21="是",'Scoring Rules'!$B$29,0)+IF(P21="是",'Scoring Rules'!$B$30,0)+IF(Q21="是",'Scoring Rules'!$B$31,0)+IF(R21="是",'Scoring Rules'!$B$32,0)+IF(S21>=8000,'Scoring Rules'!$B$35,IF(S21>=4000,'Scoring Rules'!$B$36,IF(S21>=2000,'Scoring Rules'!$B$37,'Scoring Rules'!$B$38)))) | F21: Standard | G21: Bachelor | H21: 12 | I21: 3 | J21: 9 | L21: 是 | R21: 是 | S21: 2123 | T21: Frontend; Backend/API; Data/Database; Embedded/Systems | U21: Technology; Education/Research | V21: C:\Workspace\java\scrape_indeed\soft_dav_part_1\1110.html#20908
A22: =IF(COUNTIF('Sample 20'!$B$2:$B$21,B22)>0,"是","") | B22: 20630 | C22: Software Developer | D22: =IF(E22>='Scoring Rules'!$B$3,"强",IF(E22>='Scoring Rules'!$B$4,"中","弱")) | E22: =MIN(100,H22+IF(I22>=5,'Scoring Rules'!$B$16,IF(I22>=3,'Scoring Rules'!$B$17,IF(I22>=1,'Scoring Rules'!$B$18,'Scoring Rules'!$B$19)))+IF(L22="是",'Scoring Rules'!$B$22,0)+MIN(J22*'Scoring Rules'!$B$23,'Scoring Rules'!$B$24)+IF(M22="是",'Scoring Rules'!$B$25,0)+MIN((IF(K22="",0,LEN(K22)-LEN(SUBSTITUTE(K22,";",""))+1))*'Scoring Rules'!$B$26,'Scoring Rules'!$B$27)+IF(N22="是",'Scoring Rules'!$B$28,0)+IF(O22="是",'Scoring Rules'!$B$29,0)+IF(P22="是",'Scoring Rules'!$B$30,0)+IF(Q22="是",'Scoring Rules'!$B$31,0)+IF(R22="是",'Scoring Rules'!$B$32,0)+IF(S22>=8000,'Scoring Rules'!$B$35,IF(S22>=4000,'Scoring Rules'!$B$36,IF(S22>=2000,'Scoring Rules'!$B$37,'Scoring Rules'!$B$38)))) | F22: Standard | G22: Master | H22: 16 | I22: 2 | J22: 18 | L22: 是 | O22: 是 | P22: 是 | R22: 是 | S22: 3048 | T22: Frontend; Backend/API; Data/Database; Cloud/DevOps | U22: Technology; Education/Research | V22: C:\Workspace\java\scrape_indeed\soft_dav_part_1\1111.html#20909
A23: =IF(COUNTIF('Sample 20'!$B$2:$B$21,B23)>0,"是","") | B23: 20631 | C23: Software Developer | D23: =IF(E23>='Scoring Rules'!$B$3,"强",IF(E23>='Scoring Rules'!$B$4,"中","弱")) | E23: =MIN(100,H23+IF(I23>=5,'Scoring Rules'!$B$16,IF(I23>=3,'Scoring Rules'!$B$17,IF(I23>=1,'Scoring Rules'!$B$18,'Scoring Rules'!$B$19)))+IF(L23="是",'Scoring Rules'!$B$22,0)+MIN(J23*'Scoring Rules'!$B$23,'Scoring Rules'!$B$24)+IF(M23="是",'Scoring Rules'!$B$25,0)+MIN((IF(K23="",0,LEN(K23)-LEN(SUBSTITUTE(K23,";",""))+1))*'Scoring Rules'!$B$26,'Scoring Rules'!$B$27)+IF(N23="是",'Scoring Rules'!$B$28,0)+IF(O23="是",'Scoring Rules'!$B$29,0)+IF(P23="是",'Scoring Rules'!$B$30,0)+IF(Q23="是",'Scoring Rules'!$B$31,0)+IF(R23="是",'Scoring Rules'!$B$32,0)+IF(S23>=8000,'Scoring Rules'!$B$35,IF(S23>=4000,'Scoring Rules'!$B$36,IF(S23>=2000,'Scoring Rules'!$B$37,'Scoring Rules'!$B$38)))) | F23: Standard | G23: Master | H23: 16 | I23: 3 | J23: 27 | S23: 2900 | T23: Frontend; Backend/API; Data/Database; Cloud/DevOps; Testing/Automation | U23: Technology; Education/Research; Retail/E-commerce | V23: C:\Workspace\java\scrape_indeed\soft_dav_part_1\1112.html#20910
A24: =IF(COUNTIF('Sample 20'!$B$2:$B$21,B24)>0,"是","") | B24: 20632 | C24: Software Developer | D24: =IF(E24>='Scoring Rules'!$B$3,"强",IF(E24>='Scoring Rules'!$B$4,"中","弱")) | E24: =MIN(100,H24+IF(I24>=5,'Scoring Rules'!$B$16,IF(I24>=3,'Scoring Rules'!$B$17,IF(I24>=1,'Scoring Rules'!$B$18,'Scoring Rules'!$B$19)))+IF(L24="是",'Scoring Rules'!$B$22,0)+MIN(J24*'Scoring Rules'!$B$23,'Scoring Rules'!$B$24)+IF(M24="是",'Scoring Rules'!$B$25,0)+MIN((IF(K24="",0,LEN(K24)-LEN(SUBSTITUTE(K24,";",""))+1))*'Scoring Rules'!$B$26,'Scoring Rules'!$B$27)+IF(N24="是",'Scoring Rules'!$B$28,0)+IF(O24="是",'Scoring Rules'!$B$29,0)+IF(P24="是",'Scoring Rules'!$B$30,0)+IF(Q24="是",'Scoring Rules'!$B$31,0)+IF(R24="是",'Scoring Rules'!$B$32,0)+IF(S24>=8000,'Scoring Rules'!$B$35,IF(S24>=4000,'Scoring Rules'!$B$36,IF(S24>=2000,'Scoring Rules'!$B$37,'Scoring Rules'!$B$38)))) | F24: Standard | G24: Bachelor | H24: 12 | I24: 4 | J24: 15 | L24: 是 | P24: 是 | Q24: 是 | R24: 是 | S24: 1782 | T24: Frontend; Backend/API; Data/Database; Embedded/Systems; Machine Learning | U24: Finance/Banking; Technology; Education/Research | V24: C:\Workspace\java\scrape_indeed\soft_dav_part_1\1113.html#20911
A25: =IF(COUNTIF('Sample 20'!$B$2:$B$21,B25)>0,"是","") | B25: 20634 | C25: Software Developer | D25: =IF(E25>='Scoring Rules'!$B$3,"强",IF(E25>='Scoring Rules'!$B$4,"中","弱")) | E25: =MIN(100,H25+IF(I25>=5,'Scoring Rules'!$B$16,IF(I25>=3,'Scoring Rules'!$B$17,IF(I25>=1,'Scoring Rules'!$B$18,'Scoring Rules'!$B$19)))+IF(L25="是",'Scoring Rules'!$B$22,0)+MIN(J25*'Scoring Rules'!$B$23,'Scoring Rules'!$B$24)+IF(M25="是",'Scoring Rules'!$B$25,0)+MIN((IF(K25="",0,LEN(K25)-LEN(SUBSTITUTE(K25,";",""))+1))*'Scoring Rules'!$B$26,'Scoring Rules'!$B$27)+IF(N25="是",'Scoring Rules'!$B$28,0)+IF(O25="是",'Scoring Rules'!$B$29,0)+IF(P25="是",'Scoring Rules'!$B$30,0)+IF(Q25="是",'Scoring Rules'!$B$31,0)+IF(R25="是",'Scoring Rules'!$B$32,0)+IF(S25>=8000,'Scoring Rules'!$B$35,IF(S25>=4000,'Scoring Rules'!$B$36,IF(S25>=2000,'Scoring Rules'!$B$37,'Scoring Rules'!$B$38)))) | F25: Standard | G25: Bachelor | H25: 12 | I25: 3 | J25: 28 | L25: 是 | P25: 是 | Q25: 是 | R25: 是 | S25: 3250 | T25: Frontend; Backend/API; Mobile; Data/Database; Cloud/DevOps | U25: Technology; Education/Research | V25: C:\Workspace\java\scrape_indeed\soft_dav_part_1\1115.html#20913
A26: =IF(COUNTIF('Sample 20'!$B$2:$B$21,B26)>0,"是","") | B26: 20649 | C26: Software Developer | D26: =IF(E26>='Scoring Rules'!$B$3,"强",IF(E26>='Scoring Rules'!$B$4,"中","弱")) | E26: =MIN(100,H26+IF(I26>=5,'Scoring Rules'!$B$16,IF(I26>=3,'Scoring Rules'!$B$17,IF(I26>=1,'Scoring Rules'!$B$18,'Scoring Rules'!$B$19)))+IF(L26="是",'Scoring Rules'!$B$22,0)+MIN(J26*'Scoring Rules'!$B$23,'Scoring Rules'!$B$24)+IF(M26="是",'Scoring Rules'!$B$25,0)+MIN((IF(K26="",0,LEN(K26)-LEN(SUBSTITUTE(K26,";",""))+1))*'Scoring Rules'!$B$26,'Scoring Rules'!$B$27)+IF(N26="是",'Scoring Rules'!$B$28,0)+IF(O26="是",'Scoring Rules'!$B$29,0)+IF(P26="是",'Scoring Rules'!$B$30,0)+IF(Q26="是",'Scoring Rules'!$B$31,0)+IF(R26="是",'Scoring Rules'!$B$32,0)+IF(S26>=8000,'Scoring Rules'!$B$35,IF(S26>=4000,'Scoring Rules'!$B$36,IF(S26>=2000,'Scoring Rules'!$B$37,'Scoring Rules'!$B$38)))) | F26: Standard | G26: Master | H26: 16 | I26: 2 | J26: 14 | L26: 是 | P26: 是 | R26: 是 | S26: 2040 | T26: Frontend; Backend/API; Data/Database; Machine Learning | U26: Technology; Education/Research | V26: C:\Workspace\java\scrape_indeed\soft_dav_part_1\1129.html#20928
A27: =IF(COUNTIF('Sample 20'!$B$2:$B$21,B27)>0,"是","") | B27: 20652 | C27: Software Developer | D27: =IF(E27>='Scoring Rules'!$B$3,"强",IF(E27>='Scoring Rules'!$B$4,"中","弱")) | E27: =MIN(100,H27+IF(I27>=5,'Scoring Rules'!$B$16,IF(I27>=3,'Scoring Rules'!$B$17,IF(I27>=1,'Scoring Rules'!$B$18,'Scoring Rules'!$B$19)))+IF(L27="是",'Scoring Rules'!$B$22,0)+MIN(J27*'Scoring Rules'!$B$23,'Scoring Rules'!$B$24)+IF(M27="是",'Scoring Rules'!$B$25,0)+MIN((IF(K27="",0,LEN(K27)-LEN(SUBSTITUTE(K27,";",""))+1))*'Scoring Rules'!$B$26,'Scoring Rules'!$B$27)+IF(N27="是",'Scoring Rules'!$B$28,0)+IF(O27="是",'Scoring Rules'!$B$29,0)+IF(P27="是",'Scoring Rules'!$B$30,0)+IF(Q27="是",'Scoring Rules'!$B$31,0)+IF(R27="是",'Scoring Rules'!$B$32,0)+IF(S27>=8000,'Scoring Rules'!$B$35,IF(S27>=4000,'Scoring Rules'!$B$36,IF(S27>=2000,'Scoring Rules'!$B$37,'Scoring Rules'!$B$38)))) | F27: Standard | G27: Unspecified | H27: 2 | I27: 2 | J27: 11 | L27: 是 | O27: 是 | R27: 是 | S27: 4541 | T27: Frontend; Backend/API; Data/Database | U27: Technology; Education/Research | V27: C:\Workspace\java\scrape_indeed\soft_dav_part_1\1131.html#20931
A28: =IF(COUNTIF('Sample 20'!$B$2:$B$21,B28)>0,"是","") | B28: 20653 | C28: Software Developer | D28: =IF(E28>='Scoring Rules'!$B$3,"强",IF(E28>='Scoring Rules'!$B$4,"中","弱")) | E28: =MIN(100,H28+IF(I28>=5,'Scoring Rules'!$B$16,IF(I28>=3,'Scoring Rules'!$B$17,IF(I28>=1,'Scoring Rules'!$B$18,'Scoring Rules'!$B$19)))+IF(L28="是",'Scoring Rules'!$B$22,0)+MIN(J28*'Scoring Rules'!$B$23,'Scoring Rules'!$B$24)+IF(M28="是",'Scoring Rules'!$B$25,0)+MIN((IF(K28="",0,LEN(K28)-LEN(SUBSTITUTE(K28,";",""))+1))*'Scoring Rules'!$B$26,'Scoring Rules'!$B$27)+IF(N28="是",'Scoring Rules'!$B$28,0)+IF(O28="是",'Scoring Rules'!$B$29,0)+IF(P28="是",'Scoring Rules'!$B$30,0)+IF(Q28="是",'Scoring Rules'!$B$31,0)+IF(R28="是",'Scoring Rules'!$B$32,0)+IF(S28>=8000,'Scoring Rules'!$B$35,IF(S28>=4000,'Scoring Rules'!$B$36,IF(S28>=2000,'Scoring Rules'!$B$37,'Scoring Rules'!$B$38)))) | F28: Standard | G28: Bachelor | H28: 12 | I28: 2 | J28: 12 | L28: 是 | Q28: 是 | R28: 是 | S28: 1213 | T28: Frontend; Backend/API; Data/Database | U28: Technology; Education/Research | V28: C:\Workspace\java\scrape_indeed\soft_dav_part_1\1132.html#20932
A29: =IF(COUNTIF('Sample 20'!$B$2:$B$21,B29)>0,"是","") | B29: 20654 | C29: Software Developer | D29: =IF(E29>='Scoring Rules'!$B$3,"强",IF(E29>='Scoring Rules'!$B$4,"中","弱")) | E29: =MIN(100,H29+IF(I29>=5,'Scoring Rules'!$B$16,IF(I29>=3,'Scoring Rules'!$B$17,IF(I29>=1,'Scoring Rules'!$B$18,'Scoring Rules'!$B$19)))+IF(L29="是",'Scoring Rules'!$B$22,0)+MIN(J29*'Scoring Rules'!$B$23,'Scoring Rules'!$B$24)+IF(M29="是",'Scoring Rules'!$B$25,0)+MIN((IF(K29="",0,LEN(K29)-LEN(SUBSTITUTE(K29,";",""))+1))*'Scoring Rules'!$B$26,'Scoring Rules'!$B$27)+IF(N29="是",'Scoring Rules'!$B$28,0)+IF(O29="是",'Scoring Rules'!$B$29,0)+IF(P29="是",'Scoring Rules'!$B$30,0)+IF(Q29="是",'Scoring Rules'!$B$31,0)+IF(R29="是",'Scoring Rules'!$B$32,0)+IF(S29>=8000,'Scoring Rules'!$B$35,IF(S29>=4000,'Scoring Rules'!$B$36,IF(S29>=2000,'Scoring Rules'!$B$37,'Scoring Rules'!$B$38)))) | F29: Standard | G29: Unspecified | H29: 2 | I29: 1 | J29: 19 | L29: 是 | Q29: 是 | R29: 是 | S29: 2246 | T29: Frontend; Backend/API; Data/Database; Cloud/DevOps; Embedded/Systems; Testing/Automation | U29: Finance/Banking; Technology; Education/Research | V29: C:\Workspace\java\scrape_indeed\soft_dav_part_1\1133.html#20933
A30: =IF(COUNTIF('Sample 20'!$B$2:$B$21,B30)>0,"是","") | B30: 20656 | C30: Software Developer | D30: =IF(E30>='Scoring Rules'!$B$3,"强",IF(E30>='Scoring Rules'!$B$4,"中","弱")) | E30: =MIN(100,H30+IF(I30>=5,'Scoring Rules'!$B$16,IF(I30>=3,'Scoring Rules'!$B$17,IF(I30>=1,'Scoring Rules'!$B$18,'Scoring Rules'!$B$19)))+IF(L30="是",'Scoring Rules'!$B$22,0)+MIN(J30*'Scoring Rules'!$B$23,'Scoring Rules'!$B$24)+IF(M30="是",'Scoring Rules'!$B$25,0)+MIN((IF(K30="",0,LEN(K30)-LEN(SUBSTITUTE(K30,";",""))+1))*'Scoring Rules'!$B$26,'Scoring Rules'!$B$27)+IF(N30="是",'Scoring Rules'!$B$28,0)+IF(O30="是",'Scoring Rules'!$B$29,0)+IF(P30="是",'Scoring Rules'!$B$30,0)+IF(Q30="是",'Scoring Rules'!$B$31,0)+IF(R30="是",'Scoring Rules'!$B$32,0)+IF(S30>=8000,'Scoring Rules'!$B$35,IF(S30>=4000,'Scoring Rules'!$B$36,IF(S30>=2000,'Scoring Rules'!$B$37,'Scoring Rules'!$B$38)))) | F30: Standard | G30: Bachelor | H30: 12 | I30: 4 | J30: 7 | L30: 是 | M30: 是 | O30: 是 | R30: 是 | S30: 3024 | T30: Frontend; Data/Database | U30: Technology | V30: C:\Workspace\java\scrape_indeed\soft_dav_part_1\1135.html#20935
A31: =IF(COUNTIF('Sample 20'!$B$2:$B$21,B31)>0,"是","") | B31: 20657 | C31: Software Developer | D31: =IF(E31>='Scoring Rules'!$B$3,"强",IF(E31>='Scoring Rules'!$B$4,"中","弱")) | E31: =MIN(100,H31+IF(I31>=5,'Scoring Rules'!$B$16,IF(I31>=3,'Scoring Rules'!$B$17,IF(I31>=1,'Scoring Rules'!$B$18,'Scoring Rules'!$B$19)))+IF(L31="是",'Scoring Rules'!$B$22,0)+MIN(J31*'Scoring Rules'!$B$23,'Scoring Rules'!$B$24)+IF(M31="是",'Scoring Rules'!$B$25,0)+MIN((IF(K31="",0,LEN(K31)-LEN(SUBSTITUTE(K31,";",""))+1))*'Scoring Rules'!$B$26,'Scoring Rules'!$B$27)+IF(N31="是",'Scoring Rules'!$B$28,0)+IF(O31="是",'Scoring Rules'!$B$29,0)+IF(P31="是",'Scoring Rules'!$B$30,0)+IF(Q31="是",'Scoring Rules'!$B$31,0)+IF(R31="是",'Scoring Rules'!$B$32,0)+IF(S31>=8000,'Scoring Rules'!$B$35,IF(S31>=4000,'Scoring Rules'!$B$36,IF(S31>=2000,'Scoring Rules'!$B$37,'Scoring Rules'!$B$38)))) | F31: Standard | G31: Master | H31: 16 | I31: 1 | J31: 16 | L31: 是 | R31: 是 | S31: 2164 | T31: Frontend; Backend/API; Mobile; Data/Database; Cloud/DevOps | U31: Technology; Education/Research | V31: C:\Workspace\java\scrape_indeed\soft_dav_part_1\1136.html#20936
A32: =IF(COUNTIF('Sample 20'!$B$2:$B$21,B32)>0,"是","") | B32: 20659 | C32: Software Developer | D32: =IF(E32>='Scoring Rules'!$B$3,"强",IF(E32>='Scoring Rules'!$B$4,"中","弱")) | E32: =MIN(100,H32+IF(I32>=5,'Scoring Rules'!$B$16,IF(I32>=3,'Scoring Rules'!$B$17,IF(I32>=1,'Scoring Rules'!$B$18,'Scoring Rules'!$B$19)))+IF(L32="是",'Scoring Rules'!$B$22,0)+MIN(J32*'Scoring Rules'!$B$23,'Scoring Rules'!$B$24)+IF(M32="是",'Scoring Rules'!$B$25,0)+MIN((IF(K32="",0,LEN(K32)-LEN(SUBSTITUTE(K32,";",""))+1))*'Scoring Rules'!$B$26,'Scoring Rules'!$B$27)+IF(N32="是",'Scoring Rules'!$B$28,0)+IF(O32="是",'Scoring Rules'!$B$29,0)+IF(P32="是",'Scoring Rules'!$B$30,0)+IF(Q32="是",'Scoring Rules'!$B$31,0)+IF(R32="是",'Scoring Rules'!$B$32,0)+IF(S32>=8000,'Scoring Rules'!$B$35,IF(S32>=4000,'Scoring Rules'!$B$36,IF(S32>=2000,'Scoring Rules'!$B$37,'Scoring Rules'!$B$38)))) | F32: Standard | G32: High School | H32: 5 | I32: 2 | J32: 15 | P32: 是 | Q32: 是 | R32: 是 | S32: 1650 | T32: Frontend; Backend/API; Mobile; Data/Database | U32: Technology; Education/Research | V32: C:\Workspace\java\scrape_indeed\soft_dav_part_1\1138.html#20938
A33: =IF(COUNTIF('Sample 20'!$B$2:$B$21,B33)>0,"是","") | B33: 20663 | C33: Software Developer | D33: =IF(E33>='Scoring Rules'!$B$3,"强",IF(E33>='Scoring Rules'!$B$4,"中","弱")) | E33: =MIN(100,H33+IF(I33>=5,'Scoring Rules'!$B$16,IF(I33>=3,'Scoring Rules'!$B$17,IF(I33>=1,'Scoring Rules'!$B$18,'Scoring Rules'!$B$19)))+IF(L33="是",'Scoring Rules'!$B$22,0)+MIN(J33*'Scoring Rules'!$B$23,'Scoring Rules'!$B$24)+IF(M33="是",'Scoring Rules'!$B$25,0)+MIN((IF(K33="",0,LEN(K33)-LEN(SUBSTITUTE(K33,";",""))+1))*'Scoring Rules'!$B$26,'Scoring Rules'!$B$27)+IF(N33="是",'Scoring Rules'!$B$28,0)+IF(O33="是",'Scoring Rules'!$B$29,0)+IF(P33="是",'Scoring Rules'!$B$30,0)+IF(Q33="是",'Scoring Rules'!$B$31,0)+IF(R33="是",'Scoring Rules'!$B$32,0)+IF(S33>=8000,'Scoring Rules'!$B$35,IF(S33>=4000,'Scoring Rules'!$B$36,IF(S33>=2000,'Scoring Rules'!$B$37,'Scoring Rules'!$B$38)))) | F33: Standard | G33: Bachelor | H33: 12 | I33: 5 | J33: 12 | L33: 是 | S33: 1895 | T33: Frontend; Backend/API; Data/Database | U33: Technology; Education/Research | V33: C:\Workspace\java\scrape_indeed\soft_dav_part_1\1141.html#20942
A34: =IF(COUNTIF('Sample 20'!$B$2:$B$21,B34)>0,"是","") | B34: 20665 | C34: Software Developer | D34: =IF(E34>='Scoring Rules'!$B$3,"强",IF(E34>='Scoring Rules'!$B$4,"中","弱")) | E34: =MIN(100,H34+IF(I34>=5,'Scoring Rules'!$B$16,IF(I34>=3,'Scoring Rules'!$B$17,IF(I34>=1,'Scoring Rules'!$B$18,'Scoring Rules'!$B$19)))+IF(L34="是",'Scoring Rules'!$B$22,0)+MIN(J34*'Scoring Rules'!$B$23,'Scoring Rules'!$B$24)+IF(M34="是",'Scoring Rules'!$B$25,0)+MIN((IF(K34="",0,LEN(K34)-LEN(SUBSTITUTE(K34,";",""))+1))*'Scoring Rules'!$B$26,'Scoring Rules'!$B$27)+IF(N34="是",'Scoring Rules'!$B$28,0)+IF(O34="是",'Scoring Rules'!$B$29,0)+IF(P34="是",'Scoring Rules'!$B$30,0)+IF(Q34="是",'Scoring Rules'!$B$31,0)+IF(R34="是",'Scoring Rules'!$B$32,0)+IF(S34>=8000,'Scoring Rules'!$B$35,IF(S34>=4000,'Scoring Rules'!$B$36,IF(S34>=2000,'Scoring Rules'!$B$37,'Scoring Rules'!$B$38)))) | F34: Standard | G34: Bachelor | H34: 12 | I34: 3 | J34: 10 | L34: 是 | P34: 是 | S34: 3425 | T34: Frontend; Backend/API; Data/Database | U34: Technology; Education/Research | V34: C:\Workspace\java\scrape_indeed\soft_dav_part_1\1143.html#20944
A35: =IF(COUNTIF('Sample 20'!$B$2:$B$21,B35)>0,"是","") | B35: 20666 | C35: Software Developer | D35: =IF(E35>='Scoring Rules'!$B$3,"强",IF(E35>='Scoring Rules'!$B$4,"中","弱")) | E35: =MIN(100,H35+IF(I35>=5,'Scoring Rules'!$B$16,IF(I35>=3,'Scoring Rules'!$B$17,IF(I35>=1,'Scoring Rules'!$B$18,'Scoring Rules'!$B$19)))+IF(L35="是",'Scoring Rules'!$B$22,0)+MIN(J35*'Scoring Rules'!$B$23,'Scoring Rules'!$B$24)+IF(M35="是",'Scoring Rules'!$B$25,0)+MIN((IF(K35="",0,LEN(K35)-LEN(SUBSTITUTE(K35,";",""))+1))*'Scoring Rules'!$B$26,'Scoring Rules'!$B$27)+IF(N35="是",'Scoring Rules'!$B$28,0)+IF(O35="是",'Scoring Rules'!$B$29,0)+IF(P35="是",'Scoring Rules'!$B$30,0)+IF(Q35="是",'Scoring Rules'!$B$31,0)+IF(R35="是",'Scoring Rules'!$B$32,0)+IF(S35>=8000,'Scoring Rules'!$B$35,IF(S35>=4000,'Scoring Rules'!$B$36,IF(S35>=2000,'Scoring Rules'!$B$37,'Scoring Rules'!$B$38)))) | F35: Standard | G35: Master | H35: 16 | I35: 1 | J35: 11 | Q35: 是 | S35: 1782 | T35: Frontend; Backend/API; Mobile; Data/Database | U35: Finance/Banking; Technology; Education/Research | V35: C:\Workspace\java\scrape_indeed\soft_dav_part_1\1144.html#20945
A36: =IF(COUNTIF('Sample 20'!$B$2:$B$21,B36)>0,"是","") | B36: 20667 | C36: Software Developer | D36: =IF(E36>='Scoring Rules'!$B$3,"强",IF(E36>='Scoring Rules'!$B$4,"中","弱")) | E36: =MIN(100,H36+IF(I36>=5,'Scoring Rules'!$B$16,IF(I36>=3,'Scoring Rules'!$B$17,IF(I36>=1,'Scoring Rules'!$B$18,'Scoring Rules'!$B$19)))+IF(L36="是",'Scoring Rules'!$B$22,0)+MIN(J36*'Scoring Rules'!$B$23,'Scoring Rules'!$B$24)+IF(M36="是",'Scoring Rules'!$B$25,0)+MIN((IF(K36="",0,LEN(K36)-LEN(SUBSTITUTE(K36,";",""))+1))*'Scoring Rules'!$B$26,'Scoring Rules'!$B$27)+IF(N36="是",'Scoring Rules'!$B$28,0)+IF(O36="是",'Scoring Rules'!$B$29,0)+IF(P36="是",'Scoring Rules'!$B$30,0)+IF(Q36="是",'Scoring Rules'!$B$31,0)+IF(R36="是",'Scoring Rules'!$B$32,0)+IF(S36>=8000,'Scoring Rules'!$B$35,IF(S36>=4000,'Scoring Rules'!$B$36,IF(S36>=2000,'Scoring Rules'!$B$37,'Scoring Rules'!$B$38)))) | F36: Standard | G36: Bachelor | H36: 12 | I36: 4 | J36: 17 | L36: 是 | O36: 是 | Q36: 是 | R36: 是 | S36: 3051 | T36: Frontend; Backend/API; Data/Database | U36: Technology; Telecom; Education/Research | V36: C:\Workspace\java\scrape_indeed\soft_dav_part_1\1145.html#20946
A37: =IF(COUNTIF('Sample 20'!$B$2:$B$21,B37)>0,"是","") | B37: 20669 | C37: Software Developer | D37: =IF(E37>='Scoring Rules'!$B$3,"强",IF(E37>='Scoring Rules'!$B$4,"中","弱")) | E37: =MIN(100,H37+IF(I37>=5,'Scoring Rules'!$B$16,IF(I37>=3,'Scoring Rules'!$B$17,IF(I37>=1,'Scoring Rules'!$B$18,'Scoring Rules'!$B$19)))+IF(L37="是",'Scoring Rules'!$B$22,0)+MIN(J37*'Scoring Rules'!$B$23,'Scoring Rules'!$B$24)+IF(M37="是",'Scoring Rules'!$B$25,0)+MIN((IF(K37="",0,LEN(K37)-LEN(SUBSTITUTE(K37,";",""))+1))*'Scoring Rules'!$B$26,'Scoring Rules'!$B$27)+IF(N37="是",'Scoring Rules'!$B$28,0)+IF(O37="是",'Scoring Rules'!$B$29,0)+IF(P37="是",'Scoring Rules'!$B$30,0)+IF(Q37="是",'Scoring Rules'!$B$31,0)+IF(R37="是",'Scoring Rules'!$B$32,0)+IF(S37>=8000,'Scoring Rules'!$B$35,IF(S37>=4000,'Scoring Rules'!$B$36,IF(S37>=2000,'Scoring Rules'!$B$37,'Scoring Rules'!$B$38)))) | F37: Standard | G37: Master | H37: 16 | I37: 5 | J37: 13 | L37: 是 | M37: 是 | R37: 是 | S37: 7438 | T37: Frontend; Backend/API; Data/Database; Testing/Automation | U37: Technology; Consulting; Education/Research | V37: C:\Workspace\java\scrape_indeed\soft_dav_part_1\1147.html#20948
A38: =IF(COUNTIF('Sample 20'!$B$2:$B$21,B38)>0,"是","") | B38: 20690 | C38: Software Developer | D38: =IF(E38>='Scoring Rules'!$B$3,"强",IF(E38>='Scoring Rules'!$B$4,"中","弱")) | E38: =MIN(100,H38+IF(I38>=5,'Scoring Rules'!$B$16,IF(I38>=3,'Scoring Rules'!$B$17,IF(I38>=1,'Scoring Rules'!$B$18,'Scoring Rules'!$B$19)))+IF(L38="是",'Scoring Rules'!$B$22,0)+MIN(J38*'Scoring Rules'!$B$23,'Scoring Rules'!$B$24)+IF(M38="是",'Scoring Rules'!$B$25,0)+MIN((IF(K38="",0,LEN(K38)-LEN(SUBSTITUTE(K38,";",""))+1))*'Scoring Rules'!$B$26,'Scoring Rules'!$B$27)+IF(N38="是",'Scoring Rules'!$B$28,0)+IF(O38="是",'Scoring Rules'!$B$29,0)+IF(P38="是",'Scoring Rules'!$B$30,0)+IF(Q38="是",'Scoring Rules'!$B$31,0)+IF(R38="是",'Scoring Rules'!$B$32,0)+IF(S38>=8000,'Scoring Rules'!$B$35,IF(S38>=4000,'Scoring Rules'!$B$36,IF(S38>=2000,'Scoring Rules'!$B$37,'Scoring Rules'!$B$38)))) | F38: Standard | G38: Bachelor | H38: 12 | I38: 1 | J38: 10 | L38: 是 | R38: 是 | S38: 4512 | T38: Frontend; Backend/API; Data/Database; Embedded/Systems; Testing/Automation | U38: Technology; Education/Research | V38: C:\Workspace\java\scrape_indeed\soft_dav_part_1\1168.html#20971
A39: =IF(COUNTIF('Sample 20'!$B$2:$B$21,B39)>0,"是","") | B39: 20734 | C39: Software Developer | D39: =IF(E39>='Scoring Rules'!$B$3,"强",IF(E39>='Scoring Rules'!$B$4,"中","弱")) | E39: =MIN(100,H39+IF(I39>=5,'Scoring Rules'!$B$16,IF(I39>=3,'Scoring Rules'!$B$17,IF(I39>=1,'Scoring Rules'!$B$18,'Scoring Rules'!$B$19)))+IF(L39="是",'Scoring Rules'!$B$22,0)+MIN(J39*'Scoring Rules'!$B$23,'Scoring Rules'!$B$24)+IF(M39="是",'Scoring Rules'!$B$25,0)+MIN((IF(K39="",0,LEN(K39)-LEN(SUBSTITUTE(K39,";",""))+1))*'Scoring Rules'!$B$26,'Scoring Rules'!$B$27)+IF(N39="是",'Scoring Rules'!$B$28,0)+IF(O39="是",'Scoring Rules'!$B$29,0)+IF(P39="是",'Scoring Rules'!$B$30,0)+IF(Q39="是",'Scoring Rules'!$B$31,0)+IF(R39="是",'Scoring Rules'!$B$32,0)+IF(S39>=8000,'Scoring Rules'!$B$35,IF(S39>=4000,'Scoring Rules'!$B$36,IF(S39>=2000,'Scoring Rules'!$B$37,'Scoring Rules'!$B$38)))) | F39: Standard | G39: Unspecified | H39: 2 | I39: 2 | J39: 9 | L39: 是 | N39: 是 | P39: 是 | R39: 是 | S39: 1571 | T39: Frontend; Backend/API | U39: Technology; Education/Research | V39: C:\Workspace\java\scrape_indeed\soft_dav_part_1\121.html#21018
A40: =IF(COUNTIF('Sample 20'!$B$2:$B$21,B40)>0,"是","") | B40: 20741 | C40: Software Developer | D40: =IF(E40>='Scoring Rules'!$B$3,"强",IF(E40>='Scoring Rules'!$B$4,"中","弱")) | E40: =MIN(100,H40+IF(I40>=5,'Scoring Rules'!$B$16,IF(I40>=3,'Scoring Rules'!$B$17,IF(I40>=1,'Scoring Rules'!$B$18,'Scoring Rules'!$B$19)))+IF(L40="是",'Scoring Rules'!$B$22,0)+MIN(J40*'Scoring Rules'!$B$23,'Scoring Rules'!$B$24)+IF(M40="是",'Scoring Rules'!$B$25,0)+MIN((IF(K40="",0,LEN(K40)-LEN(SUBSTITUTE(K40,";",""))+1))*'Scoring Rules'!$B$26,'Scoring Rules'!$B$27)+IF(N40="是",'Scoring Rules'!$B$28,0)+IF(O40="是",'Scoring Rules'!$B$29,0)+IF(P40="是",'Scoring Rules'!$B$30,0)+IF(Q40="是",'Scoring Rules'!$B$31,0)+IF(R40="是",'Scoring Rules'!$B$32,0)+IF(S40>=8000,'Scoring Rules'!$B$35,IF(S40>=4000,'Scoring Rules'!$B$36,IF(S40>=2000,'Scoring Rules'!$B$37,'Scoring Rules'!$B$38)))) | F40: Standard | G40: Unspecified | H40: 2 | I40: 8 | J40: 25 | L40: 是 | Q40: 是 | R40: 是 | S40: 17516 | T40: Frontend; Backend/API; Data/Database; Cloud/DevOps; Testing/Automation | U40: Finance/Banking; Technology; Consulting; Education/Research; Retail/E-commerce | V40: C:\Workspace\java\scrape_indeed\soft_dav_part_1\1216.html#21025
...

Sheet Sample 20
A1: 样本序号 | B1: Candidate ID | C1: 原始标题 | D1: 分类 | E1: 内容证据分 | F1: 资历层级 | G1: 教育层次 | H1: 教育分 | I1: 工作经历数 | J1: 技术关键词数 | K1: 明确技术证书 | L1: 有Skills段 | M1: 有证书/执照 | N1: 有Awards/Honors | O1: 有量化成果/成就 | P1: 有个人链接 | Q1: 有补充信息 | R1: 有项目/GitHub/Open Source | S1: 正文字符数 | T1: 技术方向 | U1: 行业背景 | V1: 原始来源 | W1: 入选理由 | X1: 小样本TXT
A2: 1 | B2: 22456 | C2: Software Developer | D2: =IF(E2>='Scoring Rules'!$B$3,"强",IF(E2>='Scoring Rules'!$B$4,"中","弱")) | E2: =MIN(100,H2+IF(I2>=5,'Scoring Rules'!$B$16,IF(I2>=3,'Scoring Rules'!$B$17,IF(I2>=1,'Scoring Rules'!$B$18,'Scoring Rules'!$B$19)))+IF(L2="是",'Scoring Rules'!$B$22,0)+MIN(J2*'Scoring Rules'!$B$23,'Scoring Rules'!$B$24)+IF(M2="是",'Scoring Rules'!$B$25,0)+MIN((IF(K2="",0,LEN(K2)-LEN(SUBSTITUTE(K2,";",""))+1))*'Scoring Rules'!$B$26,'Scoring Rules'!$B$27)+IF(N2="是",'Scoring Rules'!$B$28,0)+IF(O2="是",'Scoring Rules'!$B$29,0)+IF(P2="是",'Scoring Rules'!$B$30,0)+IF(Q2="是",'Scoring Rules'!$B$31,0)+IF(R2="是",'Scoring Rules'!$B$32,0)+IF(S2>=8000,'Scoring Rules'!$B$35,IF(S2>=4000,'Scoring Rules'!$B$36,IF(S2>=2000,'Scoring Rules'!$B$37,'Scoring Rules'!$B$38)))) | F2: Standard | G2: Associate | H2: 8 | I2: 3 | J2: 17 | L2: 是 | M2: 是 | N2: 是 | O2: 是 | P2: 是 | R2: 是 | S2: 3947 | T2: Frontend; Backend/API; Mobile; Data/Database; Cloud/DevOps | U2: Technology; Consulting; Education/Research; Manufacturing/Automotive | V2: C:\Workspace\java\scrape_indeed\soft_dav_part_1\2882.html#22875 | W2: Associate；3段日期化工作经历；17类软件开发关键词；有Awards/Honors；有量化成果或明确成就；有个人链接；有项目/GitHub/Open Source信息；技术方向：Frontend、Backend/API、Mobile | X2: /Users/q/Desktop/Project-Security/data/software_developer_selection/02_diverse_sample_20/01__strong__22456__Software_Developer.txt
A3: 2 | B3: 20734 | C3: Software Developer | D3: =IF(E3>='Scoring Rules'!$B$3,"强",IF(E3>='Scoring Rules'!$B$4,"中","弱")) | E3: =MIN(100,H3+IF(I3>=5,'Scoring Rules'!$B$16,IF(I3>=3,'Scoring Rules'!$B$17,IF(I3>=1,'Scoring Rules'!$B$18,'Scoring Rules'!$B$19)))+IF(L3="是",'Scoring Rules'!$B$22,0)+MIN(J3*'Scoring Rules'!$B$23,'Scoring Rules'!$B$24)+IF(M3="是",'Scoring Rules'!$B$25,0)+MIN((IF(K3="",0,LEN(K3)-LEN(SUBSTITUTE(K3,";",""))+1))*'Scoring Rules'!$B$26,'Scoring Rules'!$B$27)+IF(N3="是",'Scoring Rules'!$B$28,0)+IF(O3="是",'Scoring Rules'!$B$29,0)+IF(P3="是",'Scoring Rules'!$B$30,0)+IF(Q3="是",'Scoring Rules'!$B$31,0)+IF(R3="是",'Scoring Rules'!$B$32,0)+IF(S3>=8000,'Scoring Rules'!$B$35,IF(S3>=4000,'Scoring Rules'!$B$36,IF(S3>=2000,'Scoring Rules'!$B$37,'Scoring Rules'!$B$38)))) | F3: Standard | G3: Unspecified | H3: 2 | I3: 2 | J3: 9 | L3: 是 | N3: 是 | P3: 是 | R3: 是 | S3: 1571 | T3: Frontend; Backend/API | U3: Technology; Education/Research | V3: C:\Workspace\java\scrape_indeed\soft_dav_part_1\121.html#21018 | W3: 教育层次未明确；2段日期化工作经历；9类软件开发关键词；有Awards/Honors；有个人链接；有项目/GitHub/Open Source信息；技术方向：Frontend、Backend/API | X3: /Users/q/Desktop/Project-Security/data/software_developer_selection/02_diverse_sample_20/02__weak__20734__Software_Developer.txt
A4: 3 | B4: 22951 | C4: Software Developer | D4: =IF(E4>='Scoring Rules'!$B$3,"强",IF(E4>='Scoring Rules'!$B$4,"中","弱")) | E4: =MIN(100,H4+IF(I4>=5,'Scoring Rules'!$B$16,IF(I4>=3,'Scoring Rules'!$B$17,IF(I4>=1,'Scoring Rules'!$B$18,'Scoring Rules'!$B$19)))+IF(L4="是",'Scoring Rules'!$B$22,0)+MIN(J4*'Scoring Rules'!$B$23,'Scoring Rules'!$B$24)+IF(M4="是",'Scoring Rules'!$B$25,0)+MIN((IF(K4="",0,LEN(K4)-LEN(SUBSTITUTE(K4,";",""))+1))*'Scoring Rules'!$B$26,'Scoring Rules'!$B$27)+IF(N4="是",'Scoring Rules'!$B$28,0)+IF(O4="是",'Scoring Rules'!$B$29,0)+IF(P4="是",'Scoring Rules'!$B$30,0)+IF(Q4="是",'Scoring Rules'!$B$31,0)+IF(R4="是",'Scoring Rules'!$B$32,0)+IF(S4>=8000,'Scoring Rules'!$B$35,IF(S4>=4000,'Scoring Rules'!$B$36,IF(S4>=2000,'Scoring Rules'!$B$37,'Scoring Rules'!$B$38)))) | F4: Standard | G4: Bachelor | H4: 12 | I4: 2 | J4: 16 | L4: 是 | N4: 是 | P4: 是 | Q4: 是 | R4: 是 | S4: 3704 | T4: Frontend; Backend/API; Mobile; Data/Database; Cloud/DevOps; Machine Learning | U4: Finance/Banking; Healthcare; Technology; Education/Research | V4: C:\Workspace\java\scrape_indeed\soft_dav_part_1\56.html#23379 | W4: Bachelor；2段日期化工作经历；16类软件开发关键词；有Awards/Honors；有个人链接；有项目/GitHub/Open Source信息；技术方向：Frontend、Backend/API、Mobile | X4: /Users/q/Desktop/Project-Security/data/software_developer_selection/02_diverse_sample_20/03__medium__22951__Software_Developer.txt
A5: 4 | B5: 20545 | C5: Software Developer | D5: =IF(E5>='Scoring Rules'!$B$3,"强",IF(E5>='Scoring Rules'!$B$4,"中","弱")) | E5: =MIN(100,H5+IF(I5>=5,'Scoring Rules'!$B$16,IF(I5>=3,'Scoring Rules'!$B$17,IF(I5>=1,'Scoring Rules'!$B$18,'Scoring Rules'!$B$19)))+IF(L5="是",'Scoring Rules'!$B$22,0)+MIN(J5*'Scoring Rules'!$B$23,'Scoring Rules'!$B$24)+IF(M5="是",'Scoring Rules'!$B$25,0)+MIN((IF(K5="",0,LEN(K5)-LEN(SUBSTITUTE(K5,";",""))+1))*'Scoring Rules'!$B$26,'Scoring Rules'!$B$27)+IF(N5="是",'Scoring Rules'!$B$28,0)+IF(O5="是",'Scoring Rules'!$B$29,0)+IF(P5="是",'Scoring Rules'!$B$30,0)+IF(Q5="是",'Scoring Rules'!$B$31,0)+IF(R5="是",'Scoring Rules'!$B$32,0)+IF(S5>=8000,'Scoring Rules'!$B$35,IF(S5>=4000,'Scoring Rules'!$B$36,IF(S5>=2000,'Scoring Rules'!$B$37,'Scoring Rules'!$B$38)))) | F5: Standard | G5: Master | H5: 16 | I5: 2 | J5: 15 | K5: PMP | L5: 是 | M5: 是 | O5: 是 | R5: 是 | S5: 3360 | T5: Frontend; Backend/API; Data/Database; Cloud/DevOps; Embedded/Systems; Testing/Automation | U5: Technology; Telecom; Education/Research | V5: C:\Workspace\java\scrape_indeed\soft_dav_part_1\1030.html#20819 | W5: Master；2段日期化工作经历；15类软件开发关键词；相关证书：PMP；有量化成果或明确成就；有项目/GitHub/Open Source信息；技术方向：Frontend、Backend/API、Data/Database | X5: /Users/q/Desktop/Project-Security/data/software_developer_selection/02_diverse_sample_20/04__strong__20545__Software_Developer.txt
A6: 5 | B6: 22828 | C6: SOFTWARE DEVELOPER | D6: =IF(E6>='Scoring Rules'!$B$3,"强",IF(E6>='Scoring Rules'!$B$4,"中","弱")) | E6: =MIN(100,H6+IF(I6>=5,'Scoring Rules'!$B$16,IF(I6>=3,'Scoring Rules'!$B$17,IF(I6>=1,'Scoring Rules'!$B$18,'Scoring Rules'!$B$19)))+IF(L6="是",'Scoring Rules'!$B$22,0)+MIN(J6*'Scoring Rules'!$B$23,'Scoring Rules'!$B$24)+IF(M6="是",'Scoring Rules'!$B$25,0)+MIN((IF(K6="",0,LEN(K6)-LEN(SUBSTITUTE(K6,";",""))+1))*'Scoring Rules'!$B$26,'Scoring Rules'!$B$27)+IF(N6="是",'Scoring Rules'!$B$28,0)+IF(O6="是",'Scoring Rules'!$B$29,0)+IF(P6="是",'Scoring Rules'!$B$30,0)+IF(Q6="是",'Scoring Rules'!$B$31,0)+IF(R6="是",'Scoring Rules'!$B$32,0)+IF(S6>=8000,'Scoring Rules'!$B$35,IF(S6>=4000,'Scoring Rules'!$B$36,IF(S6>=2000,'Scoring Rules'!$B$37,'Scoring Rules'!$B$38)))) | F6: Standard | G6: High School | H6: 5 | I6: 1 | J6: 11 | P6: 是 | Q6: 是 | R6: 是 | S6: 2630 | T6: Frontend; Backend/API; Data/Database; Testing/Automation | U6: Technology; Education/Research | V6: C:\Workspace\java\scrape_indeed\soft_dav_part_1\447.html#23254 | W6: High School；1段日期化工作经历；11类软件开发关键词；有个人链接；有项目/GitHub/Open Source信息；外部佐证和成果证据较少；技术方向：Frontend、Backend/API、Data/Database | X6: /Users/q/Desktop/Project-Security/data/software_developer_selection/02_diverse_sample_20/05__weak__22828__Software_Developer.txt
A7: 6 | B7: 22156 | C7: Software Developer | D7: =IF(E7>='Scoring Rules'!$B$3,"强",IF(E7>='Scoring Rules'!$B$4,"中","弱")) | E7: =MIN(100,H7+IF(I7>=5,'Scoring Rules'!$B$16,IF(I7>=3,'Scoring Rules'!$B$17,IF(I7>=1,'Scoring Rules'!$B$18,'Scoring Rules'!$B$19)))+IF(L7="是",'Scoring Rules'!$B$22,0)+MIN(J7*'Scoring Rules'!$B$23,'Scoring Rules'!$B$24)+IF(M7="是",'Scoring Rules'!$B$25,0)+MIN((IF(K7="",0,LEN(K7)-LEN(SUBSTITUTE(K7,";",""))+1))*'Scoring Rules'!$B$26,'Scoring Rules'!$B$27)+IF(N7="是",'Scoring Rules'!$B$28,0)+IF(O7="是",'Scoring Rules'!$B$29,0)+IF(P7="是",'Scoring Rules'!$B$30,0)+IF(Q7="是",'Scoring Rules'!$B$31,0)+IF(R7="是",'Scoring Rules'!$B$32,0)+IF(S7>=8000,'Scoring Rules'!$B$35,IF(S7>=4000,'Scoring Rules'!$B$36,IF(S7>=2000,'Scoring Rules'!$B$37,'Scoring Rules'!$B$38)))) | F7: Standard | G7: Certificate | H7: 6 | I7: 3 | J7: 14 | L7: 是 | O7: 是 | S7: 2944 | T7: Frontend; Backend/API; Data/Database | U7: Technology; Telecom; Education/Research | V7: C:\Workspace\java\scrape_indeed\soft_dav_part_1\2562.html#22520 | W7: Certificate；3段日期化工作经历；14类软件开发关键词；有量化成果或明确成就；技术方向：Frontend、Backend/API、Data/Database | X7: /Users/q/Desktop/Project-Security/data/software_developer_selection/02_diverse_sample_20/06__medium__22156__Software_Developer.txt
A8: 7 | B8: 22141 | C8: Software Developer | D8: =IF(E8>='Scoring Rules'!$B$3,"强",IF(E8>='Scoring Rules'!$B$4,"中","弱")) | E8: =MIN(100,H8+IF(I8>=5,'Scoring Rules'!$B$16,IF(I8>=3,'Scoring Rules'!$B$17,IF(I8>=1,'Scoring Rules'!$B$18,'Scoring Rules'!$B$19)))+IF(L8="是",'Scoring Rules'!$B$22,0)+MIN(J8*'Scoring Rules'!$B$23,'Scoring Rules'!$B$24)+IF(M8="是",'Scoring Rules'!$B$25,0)+MIN((IF(K8="",0,LEN(K8)-LEN(SUBSTITUTE(K8,";",""))+1))*'Scoring Rules'!$B$26,'Scoring Rules'!$B$27)+IF(N8="是",'Scoring Rules'!$B$28,0)+IF(O8="是",'Scoring Rules'!$B$29,0)+IF(P8="是",'Scoring Rules'!$B$30,0)+IF(Q8="是",'Scoring Rules'!$B$31,0)+IF(R8="是",'Scoring Rules'!$B$32,0)+IF(S8>=8000,'Scoring Rules'!$B$35,IF(S8>=4000,'Scoring Rules'!$B$36,IF(S8>=2000,'Scoring Rules'!$B$37,'Scoring Rules'!$B$38)))) | F8: Standard | G8: Doctorate | H8: 18 | I8: 6 | J8: 19 | L8: 是 | Q8: 是 | R8: 是 | S8: 4492 | T8: Frontend; Backend/API; Data/Database; Cloud/DevOps | U8: Finance/Banking; Technology; Education/Research | V8: C:\Workspace\java\scrape_indeed\soft_dav_part_1\2548.html#22504 | W8: Doctorate；6段日期化工作经历；19类软件开发关键词；有项目/GitHub/Open Source信息；外部佐证和成果证据较少；技术方向：Frontend、Backend/API、Data/Database | X8: /Users/q/Desktop/Project-Security/data/software_developer_selection/02_diverse_sample_20/07__strong__22141__Software_Developer.txt
A9: 8 | B9: 23161 | C9: Software Developer | D9: =IF(E9>='Scoring Rules'!$B$3,"强",IF(E9>='Scoring Rules'!$B$4,"中","弱")) | E9: =MIN(100,H9+IF(I9>=5,'Scoring Rules'!$B$16,IF(I9>=3,'Scoring Rules'!$B$17,IF(I9>=1,'Scoring Rules'!$B$18,'Scoring Rules'!$B$19)))+IF(L9="是",'Scoring Rules'!$B$22,0)+MIN(J9*'Scoring Rules'!$B$23,'Scoring Rules'!$B$24)+IF(M9="是",'Scoring Rules'!$B$25,0)+MIN((IF(K9="",0,LEN(K9)-LEN(SUBSTITUTE(K9,";",""))+1))*'Scoring Rules'!$B$26,'Scoring Rules'!$B$27)+IF(N9="是",'Scoring Rules'!$B$28,0)+IF(O9="是",'Scoring Rules'!$B$29,0)+IF(P9="是",'Scoring Rules'!$B$30,0)+IF(Q9="是",'Scoring Rules'!$B$31,0)+IF(R9="是",'Scoring Rules'!$B$32,0)+IF(S9>=8000,'Scoring Rules'!$B$35,IF(S9>=4000,'Scoring Rules'!$B$36,IF(S9>=2000,'Scoring Rules'!$B$37,'Scoring Rules'!$B$38)))) | F9: Standard | G9: Bachelor | H9: 12 | I9: 3 | J9: 4 | R9: 是 | S9: 2282 | T9: Backend/API; Data/Database | U9: Finance/Banking; Healthcare; Technology; Education/Research; Retail/E-commerce | V9: C:\Workspace\java\scrape_indeed\soft_dav_part_1\752.html#23593 | W9: Bachelor；3段日期化工作经历；4类软件开发关键词；有项目/GitHub/Open Source信息；外部佐证和成果证据较少；技术方向：Backend/API、Data/Database | X9: /Users/q/Desktop/Project-Security/data/software_developer_selection/02_diverse_sample_20/08__weak__23161__Software_Developer.txt
A10: 9 | B10: 23372 | C10: Software Developer | D10: =IF(E10>='Scoring Rules'!$B$3,"强",IF(E10>='Scoring Rules'!$B$4,"中","弱")) | E10: =MIN(100,H10+IF(I10>=5,'Scoring Rules'!$B$16,IF(I10>=3,'Scoring Rules'!$B$17,IF(I10>=1,'Scoring Rules'!$B$18,'Scoring Rules'!$B$19)))+IF(L10="是",'Scoring Rules'!$B$22,0)+MIN(J10*'Scoring Rules'!$B$23,'Scoring Rules'!$B$24)+IF(M10="是",'Scoring Rules'!$B$25,0)+MIN((IF(K10="",0,LEN(K10)-LEN(SUBSTITUTE(K10,";",""))+1))*'Scoring Rules'!$B$26,'Scoring Rules'!$B$27)+IF(N10="是",'Scoring Rules'!$B$28,0)+IF(O10="是",'Scoring Rules'!$B$29,0)+IF(P10="是",'Scoring Rules'!$B$30,0)+IF(Q10="是",'Scoring Rules'!$B$31,0)+IF(R10="是",'Scoring Rules'!$B$32,0)+IF(S10>=8000,'Scoring Rules'!$B$35,IF(S10>=4000,'Scoring Rules'!$B$36,IF(S10>=2000,'Scoring Rules'!$B$37,'Scoring Rules'!$B$38)))) | F10: Standard | G10: High School | H10: 5 | I10: 4 | J10: 9 | L10: 是 | O10: 是 | P10: 是 | R10: 是 | S10: 1712 | T10: Frontend; Mobile; Data/Database | U10: Technology | V10: C:\Workspace\java\scrape_indeed\soft_dav_part_1\945.html#23807 | W10: High School；4段日期化工作经历；9类软件开发关键词；有量化成果或明确成就；有个人链接；有项目/GitHub/Open Source信息；技术方向：Frontend、Mobile、Data/Database | X10: /Users/q/Desktop/Project-Security/data/software_developer_selection/02_diverse_sample_20/09__medium__23372__Software_Developer.txt
A11: 10 | B11: 22992 | C11: SOFTWARE DEVELOPER | D11: =IF(E11>='Scoring Rules'!$B$3,"强",IF(E11>='Scoring Rules'!$B$4,"中","弱")) | E11: =MIN(100,H11+IF(I11>=5,'Scoring Rules'!$B$16,IF(I11>=3,'Scoring Rules'!$B$17,IF(I11>=1,'Scoring Rules'!$B$18,'Scoring Rules'!$B$19)))+IF(L11="是",'Scoring Rules'!$B$22,0)+MIN(J11*'Scoring Rules'!$B$23,'Scoring Rules'!$B$24)+IF(M11="是",'Scoring Rules'!$B$25,0)+MIN((IF(K11="",0,LEN(K11)-LEN(SUBSTITUTE(K11,";",""))+1))*'Scoring Rules'!$B$26,'Scoring Rules'!$B$27)+IF(N11="是",'Scoring Rules'!$B$28,0)+IF(O11="是",'Scoring Rules'!$B$29,0)+IF(P11="是",'Scoring Rules'!$B$30,0)+IF(Q11="是",'Scoring Rules'!$B$31,0)+IF(R11="是",'Scoring Rules'!$B$32,0)+IF(S11>=8000,'Scoring Rules'!$B$35,IF(S11>=4000,'Scoring Rules'!$B$36,IF(S11>=2000,'Scoring Rules'!$B$37,'Scoring Rules'!$B$38)))) | F11: Standard | G11: Master | H11: 16 | I11: 3 | J11: 8 | K11: Oracle/Java | M11: 是 | O11: 是 | P11: 是 | R11: 是 | S11: 2603 | T11: Backend/API; Data/Database | U11: Finance/Banking; Government/Defense; Technology; Education/Research | V11: C:\Workspace\java\scrape_indeed\soft_dav_part_1\597.html#23420 | W11: Master；3段日期化工作经历；8类软件开发关键词；相关证书：Oracle/Java；有量化成果或明确成就；有个人链接；有项目/GitHub/Open Source信息；技术方向：Backend/API、Data/Database | X11: /Users/q/Desktop/Project-Security/data/software_developer_selection/02_diverse_sample_20/10__strong__22992__Software_Developer.txt
